<sdf version='1.12'>
  <world name='empty'>
    <physics name='1ms' type='ignored'>
      <max_step_size>0.001</max_step_size>
      <real_time_factor>1</real_time_factor>
      <real_time_update_rate>1000</real_time_update_rate>
    </physics>
    <plugin name='gz::sim::systems::Physics' filename='gz-sim-physics-system'/>
    <plugin name='gz::sim::systems::UserCommands' filename='gz-sim-user-commands-system'/>
    <plugin name='gz::sim::systems::SceneBroadcaster' filename='gz-sim-scene-broadcaster-system'/>
    <plugin name='gz::sim::systems::Contact' filename='gz-sim-contact-system'/>
    <gravity>0 0 -9.8000000000000007</gravity>
    <magnetic_field>5.5644999999999998e-06 2.2875799999999999e-05 -4.2388400000000002e-05</magnetic_field>
    <atmosphere type='adiabatic'/>
    <scene>
      <ambient>0.400000006 0.400000006 0.400000006 1</ambient>
      <background>0.699999988 0.699999988 0.699999988 1</background>
      <shadows>true</shadows>
    </scene>
    <model name='ground_plane'>
      <static>true</static>
      <link name='link'>
        <collision name='collision'>
          <geometry>
            <plane>
              <normal>0 0 1</normal>
              <size>100 100</size>
            </plane>
          </geometry>
          <surface>
            <friction>
              <ode/>
            </friction>
            <bounce/>
            <contact/>
          </surface>
        </collision>
        <visual name='visual'>
          <geometry>
            <plane>
              <normal>0 0 1</normal>
              <size>100 100</size>
            </plane>
          </geometry>
          <material>
            <ambient>0.800000012 0.800000012 0.800000012 1</ambient>
            <diffuse>0.800000012 0.800000012 0.800000012 1</diffuse>
            <specular>0.800000012 0.800000012 0.800000012 1</specular>
          </material>
        </visual>
        <pose>0 0 0 0 0 0</pose>
        <inertial>
          <pose>0 0 0 0 0 0</pose>
          <mass>1</mass>
          <inertia>
            <ixx>1</ixx>
            <ixy>0</ixy>
            <ixz>0</ixz>
            <iyy>1</iyy>
            <iyz>0</iyz>
            <izz>1</izz>
          </inertia>
        </inertial>
        <enable_wind>false</enable_wind>
      </link>
      <pose>0 0 0 0 0 0</pose>
      <self_collide>false</self_collide>
      </model>
    
    
    <model name='rbot' canonical_link='chassis'>
    <pose relative_to='world'>0 0 0 0 0 0</pose>
        <link name='chassis'>
        <pose relative_to='__model__'>0 0 0 0 0 0</pose>
        
        <inertial> <!--inertial properties of the link mass, inertia matix-->
        <mass>1.14395</mass>
        <inertia>
            <ixx>0.095329</ixx>
            <ixy>0</ixy>
            <ixz>0</ixz>
            <iyy>0.381317</iyy>
            <iyz>0</iyz>
            <izz>0.476646</izz>
        </inertia>
    </inertial>
        <visual name='chasis_visual'>
          <geometry>
            <mesh>
              <uri>file:///home/as/Blender/Robot compositeLarge.dae</uri>
            </mesh>
          </geometry>
        </visual>
        <collision name='chasis_collision'>
          <geometry>
             <mesh>
              <uri>file:///home/as/Blender/Robot compositeLarge.dae</uri>
            </mesh>
          </geometry>
        </collision>
    </link>
    <link name='left_wheel'>
    <pose relative_to="chassis">0 0 0 0 0 0</pose>
    <inertial>
        <mass>1</mass>
        <inertia>
            <ixx>0.043333</ixx>
            <ixy>0</ixy>
            <ixz>0</ixz>
            <iyy>0.043333</iyy>
            <iyz>0</iyz>
            <izz>0.08</izz>
        </inertia>
    </inertial>
        <visual name='lwheel_visual'>
          <geometry>
            <mesh>
              <uri>file:///home/as/Blender/LWheelLarge.dae</uri>
            </mesh>
          </geometry>
        </visual>
        <collision name='lwheel_collision'>
          <geometry>
            <mesh>
              <uri>file:///home/as/Blender/LWheelLarge.dae</uri>
            </mesh>
          </geometry>
        </collision>
</link>
<!--The same as left wheel but with different position-->
<link name='right_wheel'>
    <pose relative_to="chassis">0 0 0 0 0 0</pose> <!--angles are in radian-->
    <inertial>
        <mass>1</mass>
        <inertia>
            <ixx>0.043333</ixx>
            <ixy>0</ixy>
            <ixz>0</ixz>
            <iyy>0.043333</iyy>
            <iyz>0</iyz>
            <izz>0.08</izz>
        </inertia>
    </inertial>
        <visual name='rwheel_visual'>
          <geometry>
            <mesh>
              <uri>file:///home/as/Blender/RWheelLarge.dae</uri>
            </mesh>
          </geometry>
        </visual>
        <collision name='rwheel_collision'>
          <geometry>
            <mesh>
              <uri>file:///home/as/Blender/RWheelLarge.dae</uri>
            </mesh>
          </geometry>
        </collision>
</link>
<frame name="caster_frame" attached_to='chassis'>
    <pose>-1.1 -0.1 0.17 0 0 0</pose>
</frame>
<!--caster wheel-->
<link name='caster'>
    <pose relative_to='caster_frame'/>
    <inertial>
        <mass>1</mass>
        <inertia>
            <ixx>0.016</ixx>
            <ixy>0</ixy>
            <ixz>0</ixz>
            <iyy>0.016</iyy>
            <iyz>0</iyz>
            <izz>0.016</izz>
        </inertia>
    </inertial>
    <visual name='visual'>
        <geometry>
            <sphere>
                <radius>0.16</radius>
            </sphere>
        </geometry>
        <material>
            <ambient>0.0 1 0.0 1</ambient>
            <diffuse>0.0 1 0.0 1</diffuse>
            <specular>0.0 1 0.0 1</specular>
        </material>
    </visual>
    <collision name='collision'>
        <geometry>
            <sphere>
                <radius>0.16</radius>
            </sphere>
        </geometry>
    </collision>
</link>
<joint name='left_wheel_joint' type='revolute'>
    <pose relative_to="left_wheel">0.09 0 0.33 0 0 0</pose>
    <parent>chassis</parent>
    <child>left_wheel</child>
        <axis>
        <xyz expressed_in='__model__'>0 1 0</xyz> <!--can be defined as any frame or even arbitrary frames-->
        <limit>
            <lower>-1.79769e+308</lower>    <!--negative infinity-->
            <upper>1.79769e+308</upper>     <!--positive infinity-->
            <effort>inf</effort>
            <velocity>inf</velocity>
        </limit>
          <dynamics>
            <spring_reference>0</spring_reference>
            <spring_stiffness>1000</spring_stiffness>
            <damping>1000</damping>
            <friction>0</friction>
          </dynamics>

    </axis>
</joint>
<joint name='right_wheel_joint' type='revolute'>
    <pose relative_to="right_wheel">0.09 0 0.33 0 0 0</pose>
    <parent>chassis</parent>
    <child>right_wheel</child>
    <axis>
        <xyz expressed_in='__model__'>0 1 0</xyz>
        <limit>
            <lower>-1.79769e+308</lower>    <!--negative infinity-->
            <upper>1.79769e+308</upper>     <!--positive infinity-->
            <effort>inf</effort>
            <velocity>inf</velocity>
        </limit>
    </axis>
</joint>
<joint name='caster_wheel' type='ball'>
    <parent>chassis</parent>
    <child>caster</child>
</joint>


      <plugin name='gz::sim::systems::DiffDrive' filename='gz-sim-diff-drive-system'>
        <left_joint>left_wheel_joint</left_joint>
        <right_joint>right_wheel_joint</right_joint>
        <wheel_separation>1.25</wheel_separation>
        <wheel_radius>0.3</wheel_radius>
        <odom_publish_frequency>1</odom_publish_frequency>
      </plugin>
      <static>false</static>
      <self_collide>false</self_collide>
    
    
    


    
</model>

        
        
        
        
        
        
    <light name='sun' type='directional'>
      <pose>0 0 10 0 0 0</pose>
      <cast_shadows>true</cast_shadows>
      <intensity>1</intensity>
      <direction>-0.5 0.10000000000000001 -0.90000000000000002</direction>
      <diffuse>0.800000012 0.800000012 0.800000012 1</diffuse>
      <specular>0.200000003 0.200000003 0.200000003 1</specular>
      <attenuation>
        <range>1000</range>
        <linear>0.0099999997764825821</linear>
        <constant>0.89999997615814209</constant>
        <quadratic>0.0010000000474974513</quadratic>
      </attenuation>
      <spot>
        <inner_angle>0</inner_angle>
        <outer_angle>0</outer_angle>
        <falloff>0</falloff>
      </spot>
    </light>
  </world>
  <gazebo>
  <plugin name="gazebo_ros_control" filename="libgazebo_ros_control.so">
    <robotNamespace>/rbot</robotNamespace>
  </plugin>
</gazebo>
</sdf>
