<sdf version='1.12'>
  <world name='empty'>
    <physics name='1ms' type='ignored'>
      <max_step_size>0.001</max_step_size>
      <real_time_factor>1</real_time_factor>
      <real_time_update_rate>1000</real_time_update_rate>
    </physics>
    <plugin name='gz::sim::systems::Physics' filename='gz-sim-physics-system'/>
    <plugin name='gz::sim::systems::SceneBroadcaster' filename='gz-sim-scene-broadcaster-system'/>
    <plugin name='gz::sim::systems::Contact' filename='gz-sim-contact-system'/>
    <plugin name='gz::sim::systems::Sensors' filename='gz-sim-sensors-system'>
      <render_engine>ogre2</render_engine>
    </plugin>
    <gravity>0 0 -9.8000000000000007</gravity>
    <magnetic_field>5.5644999999999998e-06 2.2875799999999999e-05 -4.2388400000000002e-05</magnetic_field>
    <atmosphere type='adiabatic'/>
    <scene>
      <ambient>0.400000006 0.400000006 0.400000006 1</ambient>
      <background>0.699999988 0.699999988 0.699999988 1</background>
      <shadows>true</shadows>
    </scene>
    <model name='ground_plane'>
      <static>true</static>
      <link name='link'>
        <collision name='collision'>
          <geometry>
            <plane>
              <normal>0 0 1</normal>
              <size>100 100</size>
            </plane>
          </geometry>
          <surface>
            <friction>
              <ode/>
            </friction>
            <bounce/>
            <contact/>
          </surface>
        </collision>
        <visual name='visual'>
          <geometry>
            <plane>
              <normal>0 0 1</normal>
              <size>100 100</size>
            </plane>
          </geometry>
          <material>
            <ambient>0.800000012 0.800000012 0.800000012 1</ambient>
            <diffuse>0.800000012 0.800000012 0.800000012 1</diffuse>
            <specular>0.800000012 0.800000012 0.800000012 1</specular>
          </material>
        </visual>
        <pose>0 0 0 0 0 0</pose>
        <inertial>
          <pose>0 0 0 0 0 0</pose>
          <mass>1</mass>
          <inertia>
            <ixx>1</ixx>
            <ixy>0</ixy>
            <ixz>0</ixz>
            <iyy>1</iyy>
            <iyz>0</iyz>
            <izz>1</izz>
          </inertia>
        </inertial>
        <enable_wind>false</enable_wind>
      </link>
      <pose>0 0 0 0 0 0</pose>
      <self_collide>false</self_collide>
    </model>
    <model name='rbot' canonical_link='chassis'>
      <pose>-2.0663899631976896 2.2545777786642738 4.0876373886278294e-06 4.1013828767486843e-06 3.1478962020290557e-06 0.32756224857638566</pose>
      <link name='chassis'>
        <pose>0.5 0 0.40000000000000002 0 0 0</pose>
        <inertial>
          <mass>1.14395</mass>
          <inertia>
            <ixx>0.095328999999999997</ixx>
            <ixy>0</ixy>
            <ixz>0</ixz>
            <iyy>0.38131700000000002</iyy>
            <iyz>0</iyz>
            <izz>0.47664600000000001</izz>
          </inertia>
          <pose>0 0 0 0 0 0</pose>
        </inertial>
        <visual name='visual'>
          <geometry>
            <box>
              <size>2 1 0.5</size>
            </box>
          </geometry>
          <material>
            <ambient>0 0 1 1</ambient>
            <diffuse>0 0 1 1</diffuse>
            <specular>0 0 1 1</specular>
          </material>
        </visual>
        <collision name='collision'>
          <geometry>
            <box>
              <size>2 1 0.5</size>
            </box>
          </geometry>
          <surface>
            <friction>
              <ode/>
            </friction>
            <bounce/>
            <contact/>
          </surface>
        </collision>
        <enable_wind>false</enable_wind>
      </link>
      <link name='lidar_link'>
        <pose>2.2204460492503131e-16 -8.8817841970012523e-16 0.71999999999999975 -9.5332177594212674e-22 -2.011509125350194e-21 -3.1411853071795859</pose>
        <inertial>
          <mass>0.10000000000000001</mass>
          <inertia>
            <ixx>0.00016666700000000001</ixx>
            <iyy>0.00016666700000000001</iyy>
            <izz>0.00016666700000000001</izz>
            <ixy>0</ixy>
            <ixz>0</ixz>
            <iyz>0</iyz>
          </inertia>
          <pose>0 0 0 0 0 0</pose>
        </inertial>
        <collision name='collision'>
          <geometry>
            <box>
              <size>0.29999999999999999 0.29999999999999999 0.29999999999999999</size>
            </box>
          </geometry>
          <surface>
            <friction>
              <ode/>
            </friction>
            <bounce/>
            <contact/>
          </surface>
        </collision>
        <visual name='visual'>
          <geometry>
            <box>
              <size>0.29999999999999999 0.29999999999999999 0.29999999999999999</size>
            </box>
          </geometry>
        </visual>
        <sensor name='gpu_lidar' type='gpu_lidar'>
          <pose>0 0 0 0 0 0</pose>
          <frame_id></frame_id>
          <topic>lidar2</topic>
          <update_rate>10</update_rate>
          <enable_metrics>false</enable_metrics>
          <lidar>
            <scan>
              <horizontal>
                <samples>640</samples>
                <resolution>1</resolution>
                <min_angle>-1.396263</min_angle>
                <max_angle>1.396263</max_angle>
              </horizontal>
              <vertical>
                <samples>1</samples>
                <min_angle>0</min_angle>
                <max_angle>0</max_angle>
                <resolution>1</resolution>
              </vertical>
            </scan>
            <range>
              <min>0.080000000000000002</min>
              <max>10</max>
              <resolution>0.01</resolution>
            </range>
            <noise>
              <type>none</type>
              <mean>0</mean>
              <stddev>0</stddev>
            </noise>
            <visibility_mask>4294967295</visibility_mask>
          </lidar>
        </sensor>
        <enable_wind>false</enable_wind>
      </link>
      <link name='left_wheel'>
        <pose>2.2204460492503131e-16 0.59999999999999964 0.4000000000000003 -1.5706999999999989 0.87086726181460783 6.0322899376808289e-16</pose>
        <inertial>
          <mass>1</mass>
          <inertia>
            <ixx>0.043333000000000003</ixx>
            <ixy>0</ixy>
            <ixz>0</ixz>
            <iyy>0.043333000000000003</iyy>
            <iyz>0</iyz>
            <izz>0.080000000000000002</izz>
          </inertia>
          <pose>0 0 0 0 0 0</pose>
        </inertial>
        <visual name='visual'>
          <geometry>
            <cylinder>
              <radius>0.40000000000000002</radius>
              <length>0.20000000000000001</length>
            </cylinder>
          </geometry>
          <material>
            <ambient>1 0 0 1</ambient>
            <diffuse>1 0 0 1</diffuse>
            <specular>1 0 0 1</specular>
          </material>
        </visual>
        <collision name='collision'>
          <geometry>
            <cylinder>
              <radius>0.40000000000000002</radius>
              <length>0.20000000000000001</length>
            </cylinder>
          </geometry>
          <surface>
            <friction>
              <ode/>
            </friction>
            <bounce/>
            <contact/>
          </surface>
        </collision>
        <enable_wind>false</enable_wind>
      </link>
      <link name='right_wheel'>
        <pose>4.4408920985006262e-16 -0.59999999999999964 0.39999999999999997 1.5708926535897929 1.3624259640415446 3.1415926535897927</pose>
        <inertial>
          <mass>1</mass>
          <inertia>
            <ixx>0.043333000000000003</ixx>
            <ixy>0</ixy>
            <ixz>0</ixz>
            <iyy>0.043333000000000003</iyy>
            <iyz>0</iyz>
            <izz>0.080000000000000002</izz>
          </inertia>
          <pose>0 0 0 0 0 0</pose>
        </inertial>
        <visual name='visual'>
          <geometry>
            <cylinder>
              <radius>0.40000000000000002</radius>
              <length>0.20000000000000001</length>
            </cylinder>
          </geometry>
          <material>
            <ambient>1 0 0 1</ambient>
            <diffuse>1 0 0 1</diffuse>
            <specular>1 0 0 1</specular>
          </material>
        </visual>
        <collision name='collision'>
          <geometry>
            <cylinder>
              <radius>0.40000000000000002</radius>
              <length>0.20000000000000001</length>
            </cylinder>
          </geometry>
          <surface>
            <friction>
              <ode/>
            </friction>
            <bounce/>
            <contact/>
          </surface>
        </collision>
        <enable_wind>false</enable_wind>
      </link>
      <frame name='caster_frame' attached_to='chassis'>
        <pose>0.80000000000000004 0 -0.20000000000000001 0 0 0</pose>
      </frame>
      <link name='caster'>
        <pose>1.3000000000000007 0 0.20000000000000026 0.3699138703859205 -0.24896958309803285 0.43402361158298508</pose>
        <inertial>
          <mass>1</mass>
          <inertia>
            <ixx>0.016</ixx>
            <ixy>0</ixy>
            <ixz>0</ixz>
            <iyy>0.016</iyy>
            <iyz>0</iyz>
            <izz>0.016</izz>
          </inertia>
          <pose>0 0 0 0 0 0</pose>
        </inertial>
        <visual name='visual'>
          <geometry>
            <sphere>
              <radius>0.20000000000000001</radius>
            </sphere>
          </geometry>
          <material>
            <ambient>0 1 0 1</ambient>
            <diffuse>0 1 0 1</diffuse>
            <specular>0 1 0 1</specular>
          </material>
        </visual>
        <collision name='collision'>
          <geometry>
            <sphere>
              <radius>0.20000000000000001</radius>
            </sphere>
          </geometry>
          <surface>
            <friction>
              <ode/>
            </friction>
            <bounce/>
            <contact/>
          </surface>
        </collision>
        <enable_wind>false</enable_wind>
      </link>
      <joint name='lidar_sensor_joint' type='fixed'>
        <parent>chassis</parent>
        <child>lidar_link</child>
        <pose>0 0 0 0 0 0</pose>
      </joint>
      <joint name='left_wheel_joint' type='revolute'>
        <pose>1.7347234759768071e-18 1.1102230246251565e-16 0 0 0 0</pose>
        <parent>chassis</parent>
        <child>left_wheel</child>
        <axis>
          <xyz>0 9.6326794747692026e-05 0.99999999536057438</xyz>
          <limit>
            <lower>-1.7976900000000001e+308</lower>
            <upper>1.7976900000000001e+308</upper>
            <effort>inf</effort>
            <velocity>inf</velocity>
            <stiffness>100000000</stiffness>
            <dissipation>1</dissipation>
          </limit>
          <dynamics>
            <spring_reference>0</spring_reference>
            <spring_stiffness>0</spring_stiffness>
            <damping>0</damping>
            <friction>0</friction>
          </dynamics>
        </axis>
      </joint>
      <joint name='right_wheel_joint' type='revolute'>
        <pose>5.5511151231257827e-17 2.7755575615628914e-16 0 0 0 0</pose>
        <parent>chassis</parent>
        <child>right_wheel</child>
        <axis>
          <xyz>0 9.6326794747692026e-05 0.99999999536057438</xyz>
          <limit>
            <lower>-1.7976900000000001e+308</lower>
            <upper>1.7976900000000001e+308</upper>
            <effort>inf</effort>
            <velocity>inf</velocity>
            <stiffness>100000000</stiffness>
            <dissipation>1</dissipation>
          </limit>
          <dynamics>
            <spring_reference>0</spring_reference>
            <spring_stiffness>0</spring_stiffness>
            <damping>0</damping>
            <friction>0</friction>
          </dynamics>
        </axis>
      </joint>
      <joint name='caster_wheel' type='ball'>
        <parent>chassis</parent>
        <child>caster</child>
        <pose>-2.7755575615628914e-16 0 0 0 0 0</pose>
      </joint>
      <plugin name='gz::sim::systems::DiffDrive' filename='gz-sim-diff-drive-system'>
        <left_joint>left_wheel_joint</left_joint>
        <right_joint>right_wheel_joint</right_joint>
        <wheel_separation>1.25</wheel_separation>
        <wheel_radius>0.3</wheel_radius>
        <odom_publish_frequency>1</odom_publish_frequency>
      </plugin>
      <static>false</static>
      <self_collide>false</self_collide>
    </model>
    <model name='box'>
      <pose>-5.5916552543640137 -0.16865600645542145 0.49999999991865868 1.9973360145016719e-21 2.6576393473189134e-22 2.2210091275439224e-23</pose>
      <link name='box_link'>
        <inertial>
          <inertia>
            <ixx>0.16666</ixx>
            <ixy>0</ixy>
            <ixz>0</ixz>
            <iyy>0.16666</iyy>
            <iyz>0</iyz>
            <izz>0.16666</izz>
          </inertia>
          <mass>1</mass>
          <pose>0 0 0 0 0 0</pose>
        </inertial>
        <collision name='box_collision'>
          <geometry>
            <box>
              <size>1 1 1</size>
            </box>
          </geometry>
          <surface>
            <friction>
              <ode/>
            </friction>
            <bounce/>
            <contact/>
          </surface>
        </collision>
        <visual name='box_visual'>
          <geometry>
            <box>
              <size>1 1 1</size>
            </box>
          </geometry>
          <material>
            <ambient>0.300000012 0.300000012 0.300000012 1</ambient>
            <diffuse>0.699999988 0.699999988 0.699999988 1</diffuse>
            <specular>1 1 1 1</specular>
          </material>
        </visual>
        <pose>0 0 0 0 0 0</pose>
        <enable_wind>false</enable_wind>
      </link>
      <static>false</static>
      <self_collide>false</self_collide>
    </model>
    <model name='capsule'>
      <pose>2.9485800000000002 -2.89879 0.49999999995100025 0 0 0</pose>
      <link name='capsule_link'>
        <inertial>
          <inertia>
            <ixx>0.074153999999999998</ixx>
            <ixy>0</ixy>
            <ixz>0</ixz>
            <iyy>0.074153999999999998</iyy>
            <iyz>0</iyz>
            <izz>0.018769000000000001</izz>
          </inertia>
          <mass>1</mass>
          <pose>0 0 0 0 0 0</pose>
        </inertial>
        <collision name='capsule_collision'>
          <geometry>
            <capsule>
              <radius>0.20000000000000001</radius>
              <length>0.59999999999999998</length>
            </capsule>
          </geometry>
          <surface>
            <friction>
              <ode/>
            </friction>
            <bounce/>
            <contact/>
          </surface>
        </collision>
        <visual name='capsule_visual'>
          <geometry>
            <capsule>
              <radius>0.20000000000000001</radius>
              <length>0.59999999999999998</length>
            </capsule>
          </geometry>
          <material>
            <ambient>0.300000012 0.300000012 0.300000012 1</ambient>
            <diffuse>0.699999988 0.699999988 0.699999988 1</diffuse>
            <specular>1 1 1 1</specular>
          </material>
        </visual>
        <pose>0 0 0 0 0 0</pose>
        <enable_wind>false</enable_wind>
      </link>
      <static>false</static>
      <self_collide>false</self_collide>
    </model>
    <model name='box_0'>
      <pose>-0.25312413395411876 -5.093073914735978 0.49999934217924757 3.5391266692681155e-07 9.1436426448292562e-07 1.5250055920993988</pose>
      <link name='box_link'>
        <inertial>
          <inertia>
            <ixx>0.16666</ixx>
            <ixy>0</ixy>
            <ixz>0</ixz>
            <iyy>0.16666</iyy>
            <iyz>0</iyz>
            <izz>0.16666</izz>
          </inertia>
          <mass>1</mass>
          <pose>0 0 0 0 0 0</pose>
        </inertial>
        <collision name='box_collision'>
          <geometry>
            <box>
              <size>1 1 1</size>
            </box>
          </geometry>
          <surface>
            <friction>
              <ode/>
            </friction>
            <bounce/>
            <contact/>
          </surface>
        </collision>
        <visual name='box_visual'>
          <geometry>
            <box>
              <size>1 1 1</size>
            </box>
          </geometry>
          <material>
            <ambient>0.300000012 0.300000012 0.300000012 1</ambient>
            <diffuse>0.699999988 0.699999988 0.699999988 1</diffuse>
            <specular>1 1 1 1</specular>
          </material>
        </visual>
        <pose>0 0 0 0 0 0</pose>
        <enable_wind>false</enable_wind>
      </link>
      <static>false</static>
      <self_collide>false</self_collide>
    </model>
    <model name='box_0_1'>
      <pose>-3.3463164890774411 -3.4726703863988386 0.49999955455738831 -3.3001734934684963e-08 2.0427256952425455e-10 0.11428764449116648</pose>
      <link name='box_link'>
        <inertial>
          <inertia>
            <ixx>0.16666</ixx>
            <ixy>0</ixy>
            <ixz>0</ixz>
            <iyy>0.16666</iyy>
            <iyz>0</iyz>
            <izz>0.16666</izz>
          </inertia>
          <mass>1</mass>
          <pose>0 0 0 0 0 0</pose>
        </inertial>
        <collision name='box_collision'>
          <geometry>
            <box>
              <size>1 1 1</size>
            </box>
          </geometry>
          <surface>
            <friction>
              <ode/>
            </friction>
            <bounce/>
            <contact/>
          </surface>
        </collision>
        <visual name='box_visual'>
          <geometry>
            <box>
              <size>1 1 1</size>
            </box>
          </geometry>
          <material>
            <ambient>0.300000012 0.300000012 0.300000012 1</ambient>
            <diffuse>0.699999988 0.699999988 0.699999988 1</diffuse>
            <specular>1 1 1 1</specular>
          </material>
        </visual>
        <pose>0 0 0 0 0 0</pose>
        <enable_wind>false</enable_wind>
      </link>
      <static>false</static>
      <self_collide>false</self_collide>
    </model>
    <model name='ground_plane_1'>
      <static>true</static>
      <link name='link'>
        <collision name='collision'>
          <geometry>
            <plane>
              <normal>0 0 1</normal>
              <size>100 100</size>
            </plane>
          </geometry>
          <surface>
            <friction>
              <ode/>
            </friction>
            <bounce/>
            <contact/>
          </surface>
        </collision>
        <visual name='visual'>
          <geometry>
            <plane>
              <normal>0 0 1</normal>
              <size>100 100</size>
            </plane>
          </geometry>
          <material>
            <ambient>0.800000012 0.800000012 0.800000012 1</ambient>
            <diffuse>0.800000012 0.800000012 0.800000012 1</diffuse>
            <specular>0.800000012 0.800000012 0.800000012 1</specular>
          </material>
        </visual>
        <pose>0 0 0 0 0 0</pose>
        <inertial>
          <pose>0 0 0 0 0 0</pose>
          <mass>1</mass>
          <inertia>
            <ixx>1</ixx>
            <ixy>0</ixy>
            <ixz>0</ixz>
            <iyy>1</iyy>
            <iyz>0</iyz>
            <izz>1</izz>
          </inertia>
        </inertial>
        <enable_wind>false</enable_wind>
      </link>
      <pose>1.05586 -4.1446100000000001 0 0 0 0</pose>
      <self_collide>false</self_collide>
    </model>
    <model name='box_0_2'>
      <pose>-4.68900904537852 1.9216470482632351 0.49999950526093739 2.3294689815296981e-07 -3.1378279583149537e-07 0.84903557029180521</pose>
      <link name='box_link'>
        <inertial>
          <inertia>
            <ixx>0.16666</ixx>
            <ixy>0</ixy>
            <ixz>0</ixz>
            <iyy>0.16666</iyy>
            <iyz>0</iyz>
            <izz>0.16666</izz>
          </inertia>
          <mass>1</mass>
          <pose>0 0 0 0 0 0</pose>
        </inertial>
        <collision name='box_collision'>
          <geometry>
            <box>
              <size>1 1 1</size>
            </box>
          </geometry>
          <surface>
            <friction>
              <ode/>
            </friction>
            <bounce/>
            <contact/>
          </surface>
        </collision>
        <visual name='box_visual'>
          <geometry>
            <box>
              <size>1 1 1</size>
            </box>
          </geometry>
          <material>
            <ambient>0.300000012 0.300000012 0.300000012 1</ambient>
            <diffuse>0.699999988 0.699999988 0.699999988 1</diffuse>
            <specular>1 1 1 1</specular>
          </material>
        </visual>
        <pose>0 0 0 0 0 0</pose>
        <enable_wind>false</enable_wind>
      </link>
      <static>false</static>
      <self_collide>false</self_collide>
    </model>
    <model name='box_0_2_1'>
      <pose>2.6613099999999998 1.34623 0.49999999995099875 -5.3766204913949038e-22 9.3620637225482676e-22 1.8634424196808295e-22</pose>
      <link name='box_link'>
        <inertial>
          <inertia>
            <ixx>0.16666</ixx>
            <ixy>0</ixy>
            <ixz>0</ixz>
            <iyy>0.16666</iyy>
            <iyz>0</iyz>
            <izz>0.16666</izz>
          </inertia>
          <mass>1</mass>
          <pose>0 0 0 0 0 0</pose>
        </inertial>
        <collision name='box_collision'>
          <geometry>
            <box>
              <size>1 1 1</size>
            </box>
          </geometry>
          <surface>
            <friction>
              <ode/>
            </friction>
            <bounce/>
            <contact/>
          </surface>
        </collision>
        <visual name='box_visual'>
          <geometry>
            <box>
              <size>1 1 1</size>
            </box>
          </geometry>
          <material>
            <ambient>0.300000012 0.300000012 0.300000012 1</ambient>
            <diffuse>0.699999988 0.699999988 0.699999988 1</diffuse>
            <specular>1 1 1 1</specular>
          </material>
        </visual>
        <pose>0 0 0 0 0 0</pose>
        <enable_wind>false</enable_wind>
      </link>
      <static>false</static>
      <self_collide>false</self_collide>
    </model>
    <model name='cylinder'>
      <pose>-1.1454175226567476 4.1239940717810395 0.49999999882734925 -2.3304368570349084e-09 9.6438512263592827e-10 -0.14370101454611803</pose>
      <link name='cylinder_link'>
        <inertial>
          <inertia>
            <ixx>0.14580000000000001</ixx>
            <ixy>0</ixy>
            <ixz>0</ixz>
            <iyy>0.14580000000000001</iyy>
            <iyz>0</iyz>
            <izz>0.125</izz>
          </inertia>
          <mass>1</mass>
          <pose>0 0 0 0 0 0</pose>
        </inertial>
        <collision name='cylinder_collision'>
          <geometry>
            <cylinder>
              <radius>0.5</radius>
              <length>1</length>
            </cylinder>
          </geometry>
          <surface>
            <friction>
              <ode/>
            </friction>
            <bounce/>
            <contact/>
          </surface>
        </collision>
        <visual name='cylinder_visual'>
          <geometry>
            <cylinder>
              <radius>0.5</radius>
              <length>1</length>
            </cylinder>
          </geometry>
          <material>
            <ambient>0.300000012 0.300000012 0.300000012 1</ambient>
            <diffuse>0.699999988 0.699999988 0.699999988 1</diffuse>
            <specular>1 1 1 1</specular>
          </material>
        </visual>
        <pose>0 0 0 0 0 0</pose>
        <enable_wind>false</enable_wind>
      </link>
      <static>false</static>
      <self_collide>false</self_collide>
    </model>
    <light name='sun' type='directional'>
      <pose>0 0 10 0 0 0</pose>
      <cast_shadows>true</cast_shadows>
      <intensity>1</intensity>
      <direction>-0.5 0.10000000000000001 -0.90000000000000002</direction>
      <diffuse>0.800000012 0.800000012 0.800000012 1</diffuse>
      <specular>0.200000003 0.200000003 0.200000003 1</specular>
      <attenuation>
        <range>1000</range>
        <linear>0.0099999997764825821</linear>
        <constant>0.89999997615814209</constant>
        <quadratic>0.0010000000474974513</quadratic>
      </attenuation>
      <spot>
        <inner_angle>0</inner_angle>
        <outer_angle>0</outer_angle>
        <falloff>0</falloff>
      </spot>
    </light>
  </world>
</sdf>
