<sdf version='1.12'>
  <world name='visualize_lidar_world'>
    <physics name='1ms' type='ignored'>
      <max_step_size>0.001</max_step_size>
      <real_time_factor>1</real_time_factor>
      <real_time_update_rate>1000</real_time_update_rate>
    </physics>
    <plugin name='gz::sim::systems::Physics' filename='gz-sim-physics-system'/>
    <plugin name='gz::sim::systems::Sensors' filename='gz-sim-sensors-system'>
      <render_engine>ogre2</render_engine>
    </plugin>
    <plugin name='gz::sim::systems::SceneBroadcaster' filename='gz-sim-scene-broadcaster-system'/>
    <gui fullscreen='false'>
      <plugin name='3D View' filename='MinimalScene'>
        <gz-gui>
          <title>3D View</title>
          <property type='bool' key='showTitleBar'>false</property>
          <property type='string' key='state'>docked</property>
        </gz-gui>
        <engine>ogre2</engine>
        <scene>scene</scene>
        <ambient_light>0.4 0.4 0.4</ambient_light>
        <background_color>0.8 0.8 0.8</background_color>
        <camera_pose>-6 0 6 0 0.5 0</camera_pose>
      </plugin>
      <plugin name='Entity context menu' filename='EntityContextMenuPlugin'>
        <gz-gui>
          <property key='state' type='string'>floating</property>
          <property key='width' type='double'>5</property>
          <property key='height' type='double'>5</property>
          <property key='showTitleBar' type='bool'>false</property>
        </gz-gui>
      </plugin>
      <plugin name='Scene Manager' filename='GzSceneManager'>
        <gz-gui>
          <property key='resizable' type='bool'>false</property>
          <property key='width' type='double'>5</property>
          <property key='height' type='double'>5</property>
          <property key='state' type='string'>floating</property>
          <property key='showTitleBar' type='bool'>false</property>
        </gz-gui>
      </plugin>
      <plugin name='Interactive view control' filename='InteractiveViewControl'>
        <gz-gui>
          <property key='resizable' type='bool'>false</property>
          <property key='width' type='double'>5</property>
          <property key='height' type='double'>5</property>
          <property key='state' type='string'>floating</property>
          <property key='showTitleBar' type='bool'>false</property>
        </gz-gui>
      </plugin>
      <plugin name='Camera Tracking' filename='CameraTracking'>
        <gz-gui>
          <property key='resizable' type='bool'>false</property>
          <property key='width' type='double'>5</property>
          <property key='height' type='double'>5</property>
          <property key='state' type='string'>floating</property>
          <property key='showTitleBar' type='bool'>false</property>
        </gz-gui>
      </plugin>
      <plugin name='World control' filename='WorldControl'>
        <gz-gui>
          <title>World control</title>
          <property type='bool' key='showTitleBar'>false</property>
          <property type='bool' key='resizable'>false</property>
          <property type='double' key='height'>72</property>
          <property type='double' key='z'>1</property>
          <property type='string' key='state'>floating</property>
          <anchors target='3D View'>
            <line own='left' target='left'/>
            <line own='bottom' target='bottom'/>
          </anchors>
        </gz-gui>
        <play_pause>true</play_pause>
        <step>true</step>
        <start_paused>true</start_paused>
        <use_event>true</use_event>
      </plugin>
      <plugin name='World stats' filename='WorldStats'>
        <gz-gui>
          <title>World stats</title>
          <property type='bool' key='showTitleBar'>false</property>
          <property type='bool' key='resizable'>false</property>
          <property type='double' key='height'>110</property>
          <property type='double' key='width'>290</property>
          <property type='double' key='z'>1</property>
          <property type='string' key='state'>floating</property>
          <anchors target='3D View'>
            <line own='right' target='right'/>
            <line own='bottom' target='bottom'/>
          </anchors>
        </gz-gui>
        <sim_time>true</sim_time>
        <real_time>true</real_time>
        <real_time_factor>true</real_time_factor>
        <iterations>true</iterations>
      </plugin>
      <plugin name='Visualize Lidar' filename='VisualizeLidar'/>
      <plugin name='Component inspector' filename='ComponentInspector'>
        <gz-gui>
          <property type='string' key='state'>docked</property>
        </gz-gui>
      </plugin>
      <plugin name='Entity tree' filename='EntityTree'>
        <gz-gui>
          <property type='string' key='state'>docked</property>
        </gz-gui>
      </plugin>
    </gui>
    <gravity>0 0 -9.8000000000000007</gravity>
    <magnetic_field>5.5644999999999998e-06 2.2875799999999999e-05 -4.2388400000000002e-05</magnetic_field>
    <atmosphere type='adiabatic'/>
    <scene>
      <ambient>0.400000006 0.400000006 0.400000006 1</ambient>
      <background>0.699999988 0.699999988 0.699999988 1</background>
      <shadows>true</shadows>
    </scene>
    <model name='ground_plane'>
      <static>true</static>
      <link name='link'>
        <collision name='collision'>
          <geometry>
            <box>
              <size>20 20 0.10000000000000001</size>
            </box>
          </geometry>
          <surface>
            <friction>
              <ode/>
            </friction>
            <bounce/>
            <contact/>
          </surface>
        </collision>
        <visual name='visual'>
          <geometry>
            <box>
              <size>20 20 0.10000000000000001</size>
            </box>
          </geometry>
          <material>
            <ambient>0.800000012 0.800000012 0.800000012 1</ambient>
            <diffuse>0.800000012 0.800000012 0.800000012 1</diffuse>
            <specular>0.800000012 0.800000012 0.800000012 1</specular>
          </material>
        </visual>
        <pose>0 0 0 0 0 0</pose>
        <inertial>
          <pose>0 0 0 0 0 0</pose>
          <mass>1</mass>
          <inertia>
            <ixx>1</ixx>
            <ixy>0</ixy>
            <ixz>0</ixz>
            <iyy>1</iyy>
            <iyz>0</iyz>
            <izz>1</izz>
          </inertia>
        </inertial>
        <enable_wind>false</enable_wind>
      </link>
      <pose>0 0 0 0 0 0</pose>
      <self_collide>false</self_collide>
    </model>
    <model name='box'>
      <pose>-0.067625888703758005 -0.92842977219727185 0.54999939641022433 1.1801247568903654e-06 4.1964606762521637e-09 0.0026380061637295885</pose>
      <link name='box_link'>
        <inertial>
          <inertia>
            <ixx>1</ixx>
            <ixy>0</ixy>
            <ixz>0</ixz>
            <iyy>1</iyy>
            <iyz>0</iyz>
            <izz>1</izz>
          </inertia>
          <mass>1</mass>
          <pose>0 0 0 0 0 0</pose>
        </inertial>
        <collision name='box_collision'>
          <geometry>
            <box>
              <size>1 1 1</size>
            </box>
          </geometry>
          <surface>
            <friction>
              <ode/>
            </friction>
            <bounce/>
            <contact/>
          </surface>
        </collision>
        <visual name='box_visual'>
          <geometry>
            <box>
              <size>1 1 1</size>
            </box>
          </geometry>
          <material>
            <ambient>1 0 0 1</ambient>
            <diffuse>1 0 0 1</diffuse>
            <specular>1 0 0 1</specular>
          </material>
        </visual>
        <pose>0 0 0 0 0 0</pose>
        <enable_wind>false</enable_wind>
      </link>
      <static>false</static>
      <self_collide>false</self_collide>
    </model>
    <model name='model_with_lidar'>
      <pose>4 -6.9388939039072284e-18 0.5 0 0 3.1400000000000001</pose>
      <link name='link'>
        <pose>0.050000000000000003 0.050000000000000003 0.050000000000000003 0 0 0</pose>
        <inertial>
          <mass>0.10000000000000001</mass>
          <inertia>
            <ixx>0.00016666700000000001</ixx>
            <iyy>0.00016666700000000001</iyy>
            <izz>0.00016666700000000001</izz>
            <ixy>0</ixy>
            <ixz>0</ixz>
            <iyz>0</iyz>
          </inertia>
          <pose>0 0 0 0 0 0</pose>
        </inertial>
        <collision name='collision'>
          <geometry>
            <box>
              <size>0.10000000000000001 0.10000000000000001 0.10000000000000001</size>
            </box>
          </geometry>
          <surface>
            <friction>
              <ode/>
            </friction>
            <bounce/>
            <contact/>
          </surface>
        </collision>
        <visual name='visual'>
          <geometry>
            <box>
              <size>0.10000000000000001 0.10000000000000001 0.10000000000000001</size>
            </box>
          </geometry>
        </visual>
        <sensor name='gpu_lidar' type='gpu_lidar'>
          <pose>0 0 0 0 0 0</pose>
          <frame_id></frame_id>
          <topic>lidar</topic>
          <update_rate>10</update_rate>
          <enable_metrics>false</enable_metrics>
          <lidar>
            <scan>
              <horizontal>
                <samples>640</samples>
                <resolution>1</resolution>
                <min_angle>-1.396263</min_angle>
                <max_angle>1.396263</max_angle>
              </horizontal>
              <vertical>
                <samples>16</samples>
                <min_angle>-0.261799</min_angle>
                <max_angle>0.261799</max_angle>
                <resolution>1</resolution>
              </vertical>
            </scan>
            <range>
              <min>0.080000000000000002</min>
              <max>10</max>
              <resolution>0.01</resolution>
            </range>
            <noise>
              <type>none</type>
              <mean>0</mean>
              <stddev>0</stddev>
            </noise>
            <visibility_mask>4294967295</visibility_mask>
          </lidar>
        </sensor>
        <enable_wind>false</enable_wind>
      </link>
      <static>true</static>
      <self_collide>false</self_collide>
    </model>
    <model name='vehicle_blue'>
      <pose>-3.9999999923594709 -1.3679798219924739e-14 0.37499916356134794 -6.48428380151821e-15 -3.6334661473190628e-09 -3.9593826131905451e-18</pose>
      <link name='chassis'>
        <pose>-0.15142700000000001 0 0.17499999999999999 0 0 0</pose>
        <inertial>
          <mass>1.14395</mass>
          <inertia>
            <ixx>0.126164</ixx>
            <ixy>0</ixy>
            <ixz>0</ixz>
            <iyy>0.41651899999999997</iyy>
            <iyz>0</iyz>
            <izz>0.481014</izz>
          </inertia>
          <pose>0 0 0 0 0 0</pose>
        </inertial>
        <visual name='visual'>
          <geometry>
            <box>
              <size>2.0114200000000002 1 0.56872599999999995</size>
            </box>
          </geometry>
          <material>
            <ambient>0.5 0.5 1 1</ambient>
            <diffuse>0.5 0.5 1 1</diffuse>
            <specular>0 0 1 1</specular>
          </material>
        </visual>
        <collision name='collision'>
          <geometry>
            <box>
              <size>2.0114200000000002 1 0.56872599999999995</size>
            </box>
          </geometry>
          <surface>
            <friction>
              <ode/>
            </friction>
            <bounce/>
            <contact/>
          </surface>
        </collision>
        <enable_wind>false</enable_wind>
      </link>
      <link name='lidar_link'>
        <pose>-4.4408920985006262e-16 0 0.49999999999999994 0 -1.2836918464498039e-32 0</pose>
        <inertial>
          <mass>0.10000000000000001</mass>
          <inertia>
            <ixx>0.00016666700000000001</ixx>
            <iyy>0.00016666700000000001</iyy>
            <izz>0.00016666700000000001</izz>
            <ixy>0</ixy>
            <ixz>0</ixz>
            <iyz>0</iyz>
          </inertia>
          <pose>0 0 0 0 0 0</pose>
        </inertial>
        <collision name='collision'>
          <geometry>
            <box>
              <size>0.10000000000000001 0.10000000000000001 0.10000000000000001</size>
            </box>
          </geometry>
          <surface>
            <friction>
              <ode/>
            </friction>
            <bounce/>
            <contact/>
          </surface>
        </collision>
        <visual name='visual'>
          <geometry>
            <box>
              <size>0.10000000000000001 0.10000000000000001 0.10000000000000001</size>
            </box>
          </geometry>
        </visual>
        <sensor name='gpu_lidar' type='gpu_lidar'>
          <pose>0 0 0 0 0 0</pose>
          <frame_id></frame_id>
          <topic>lidar2</topic>
          <update_rate>10</update_rate>
          <enable_metrics>false</enable_metrics>
          <lidar>
            <scan>
              <horizontal>
                <samples>640</samples>
                <resolution>1</resolution>
                <min_angle>-1.396263</min_angle>
                <max_angle>1.396263</max_angle>
              </horizontal>
              <vertical>
                <samples>1</samples>
                <min_angle>0</min_angle>
                <max_angle>0</max_angle>
                <resolution>1</resolution>
              </vertical>
            </scan>
            <range>
              <min>0.080000000000000002</min>
              <max>10</max>
              <resolution>0.01</resolution>
            </range>
            <noise>
              <type>none</type>
              <mean>0</mean>
              <stddev>0</stddev>
            </noise>
            <visibility_mask>4294967295</visibility_mask>
          </lidar>
        </sensor>
        <enable_wind>false</enable_wind>
      </link>
      <link name='left_wheel'>
        <pose>0.55428300005964193 0.62502899999999995 -0.024999943948802839 -1.5706999999999987 1.9880640913641687e-10 3.5080083543520347e-21</pose>
        <inertial>
          <mass>2</mass>
          <inertia>
            <ixx>0.14583299999999999</ixx>
            <ixy>0</ixy>
            <ixz>0</ixz>
            <iyy>0.14583299999999999</iyy>
            <iyz>0</iyz>
            <izz>0.125</izz>
          </inertia>
          <pose>0 0 0 0 0 0</pose>
        </inertial>
        <visual name='visual'>
          <geometry>
            <sphere>
              <radius>0.29999999999999999</radius>
            </sphere>
          </geometry>
          <material>
            <ambient>0.200000003 0.200000003 0.200000003 1</ambient>
            <diffuse>0.200000003 0.200000003 0.200000003 1</diffuse>
            <specular>0.200000003 0.200000003 0.200000003 1</specular>
          </material>
        </visual>
        <collision name='collision'>
          <geometry>
            <sphere>
              <radius>0.29999999999999999</radius>
            </sphere>
          </geometry>
          <surface>
            <friction>
              <ode/>
            </friction>
            <bounce/>
            <contact/>
          </surface>
        </collision>
        <enable_wind>false</enable_wind>
      </link>
      <link name='right_wheel'>
        <pose>0.55428200005964223 -0.62502900000000006 -0.024999943948803116 -1.5706999999999987 1.9880640915551135e-10 3.5098178119419944e-21</pose>
        <inertial>
          <mass>2</mass>
          <inertia>
            <ixx>0.14583299999999999</ixx>
            <ixy>0</ixy>
            <ixz>0</ixz>
            <iyy>0.14583299999999999</iyy>
            <iyz>0</iyz>
            <izz>0.125</izz>
          </inertia>
          <pose>0 0 0 0 0 0</pose>
        </inertial>
        <visual name='visual'>
          <geometry>
            <sphere>
              <radius>0.29999999999999999</radius>
            </sphere>
          </geometry>
          <material>
            <ambient>0.200000003 0.200000003 0.200000003 1</ambient>
            <diffuse>0.200000003 0.200000003 0.200000003 1</diffuse>
            <specular>0.200000003 0.200000003 0.200000003 1</specular>
          </material>
        </visual>
        <collision name='collision'>
          <geometry>
            <sphere>
              <radius>0.29999999999999999</radius>
            </sphere>
          </geometry>
          <surface>
            <friction>
              <ode/>
            </friction>
            <bounce/>
            <contact/>
          </surface>
        </collision>
        <enable_wind>false</enable_wind>
      </link>
      <link name='caster'>
        <pose>-0.95713800000000093 0 -0.125 6.0979536902564912e-17 -2.3046617859383212e-15 3.9591553400022558e-18</pose>
        <inertial>
          <mass>1</mass>
          <inertia>
            <ixx>0.10000000000000001</ixx>
            <ixy>0</ixy>
            <ixz>0</ixz>
            <iyy>0.10000000000000001</iyy>
            <iyz>0</iyz>
            <izz>0.10000000000000001</izz>
          </inertia>
          <pose>0 0 0 0 0 0</pose>
        </inertial>
        <visual name='visual'>
          <geometry>
            <sphere>
              <radius>0.20000000000000001</radius>
            </sphere>
          </geometry>
          <material>
            <ambient>0.200000003 0.200000003 0.200000003 1</ambient>
            <diffuse>0.200000003 0.200000003 0.200000003 1</diffuse>
            <specular>0.200000003 0.200000003 0.200000003 1</specular>
          </material>
        </visual>
        <collision name='collision'>
          <geometry>
            <sphere>
              <radius>0.20000000000000001</radius>
            </sphere>
          </geometry>
          <surface>
            <friction>
              <ode/>
            </friction>
            <bounce/>
            <contact/>
          </surface>
        </collision>
        <enable_wind>false</enable_wind>
      </link>
      <joint name='lidar_sensor_joint' type='fixed'>
        <parent>chassis</parent>
        <child>lidar_link</child>
        <pose>0 0 0 0 0 0</pose>
      </joint>
      <joint name='left_wheel_joint' type='revolute'>
        <parent>chassis</parent>
        <child>left_wheel</child>
        <axis>
          <xyz>0 0 1</xyz>
          <limit>
            <lower>-1.7976900000000001e+308</lower>
            <upper>1.7976900000000001e+308</upper>
            <effort>inf</effort>
            <velocity>inf</velocity>
            <stiffness>100000000</stiffness>
            <dissipation>1</dissipation>
          </limit>
          <dynamics>
            <spring_reference>0</spring_reference>
            <spring_stiffness>0</spring_stiffness>
            <damping>0</damping>
            <friction>0</friction>
          </dynamics>
        </axis>
        <pose>0 0 1.1102230246251565e-16 0 0 0</pose>
      </joint>
      <joint name='right_wheel_joint' type='revolute'>
        <parent>chassis</parent>
        <child>right_wheel</child>
        <axis>
          <xyz>0 0 1</xyz>
          <limit>
            <lower>-1.7976900000000001e+308</lower>
            <upper>1.7976900000000001e+308</upper>
            <effort>inf</effort>
            <velocity>inf</velocity>
            <stiffness>100000000</stiffness>
            <dissipation>1</dissipation>
          </limit>
          <dynamics>
            <spring_reference>0</spring_reference>
            <spring_stiffness>0</spring_stiffness>
            <damping>0</damping>
            <friction>0</friction>
          </dynamics>
        </axis>
        <pose>-1.1102230246251565e-16 0 0 0 0 0</pose>
      </joint>
      <joint name='caster_wheel' type='ball'>
        <parent>chassis</parent>
        <child>caster</child>
        <pose>0 0 0 0 0 0</pose>
      </joint>
      <plugin name='gz::sim::systems::DiffDrive' filename='gz-sim-diff-drive-system'>
        <left_joint>left_wheel_joint</left_joint>
        <right_joint>right_wheel_joint</right_joint>
        <wheel_separation>1.25</wheel_separation>
        <wheel_radius>0.3</wheel_radius>
        <odom_publish_frequency>1</odom_publish_frequency>
      </plugin>
      <static>false</static>
      <self_collide>false</self_collide>
    </model>
    <model name='playground'>
      <static>true</static>
      <link name='link'>
        <collision name='collision'>
          <geometry>
            <mesh>
              <uri>https://fuel.gazebosim.org/1.0/openrobotics/models/playground/4/files/meshes/playground.dae</uri>
            </mesh>
          </geometry>
        </collision>
        <visual name='visual'>
          <geometry>
            <mesh>
              <uri>https://fuel.gazebosim.org/1.0/openrobotics/models/playground/4/files/meshes/playground.dae</uri>
            </mesh>
          </geometry>
        </visual>
        <pose>0 0 0 0 0 0</pose>
        <inertial>
          <pose>0 0 0 0 0 0</pose>
          <mass>1</mass>
          <inertia>
            <ixx>1</ixx>
            <ixy>0</ixy>
            <ixz>0</ixz>
            <iyy>1</iyy>
            <iyz>0</iyz>
            <izz>1</izz>
          </inertia>
        </inertial>
        <enable_wind>false</enable_wind>
      </link>
      <pose>0 0 0 0 0 1.5699999999999998</pose>
      <self_collide>false</self_collide>
    </model>
    <light name='sun' type='directional'>
      <pose>0 0 10 0 0 0</pose>
      <cast_shadows>true</cast_shadows>
      <intensity>1</intensity>
      <direction>-0.5 0.10000000000000001 -0.90000000000000002</direction>
      <diffuse>0.800000012 0.800000012 0.800000012 1</diffuse>
      <specular>0.200000003 0.200000003 0.200000003 1</specular>
      <attenuation>
        <range>1000</range>
        <linear>0.01</linear>
        <constant>0.90000000000000002</constant>
        <quadratic>0.001</quadratic>
      </attenuation>
      <spot>
        <inner_angle>0</inner_angle>
        <outer_angle>0</outer_angle>
        <falloff>0</falloff>
      </spot>
    </light>
  </world>
</sdf>
